<?xml version="1.0"?>
<robot xmlns:xacro="http://www.ros.org/wiki/xacro" name="create_2">

	<xacro:property name="body_rad" value="0.17425"/>
	<xacro:property name="body_h" value="0.09"/>
	<xacro:property name="wheel_rad" value="0.036"/>
	<xacro:property name="wheel_h" value="0.02"/>
	<xacro:property name="b_mass" value="3.58"/>
	<xacro:property name="w_mass" value="0.2"/>
	
	<material name="black">
		<color rgba="0 0 0 1"/>
	</material>

	<material name="dark grey">
		<color rgba="0.1 0.1 0.1 1"/>
	</material>

	<link name="base_link">
		<visual>
			<geometry>
				<cylinder length="${body_h}" radius="${body_rad}"/>
			</geometry>
			<material name="dark grey"/>
		</visual>
		<collision>
			<geometry>
				<cylinder length="${body_h}" radius="${body_rad}"/>
			</geometry>
		</collision>
		<inertial>
			<mass value="${b_mass}"/>	
			<inertia ixx="0.0296" ixy="0.0" ixz="0.0" iyy="0.0296" iyz="0.0" izz="0.054"/>
		</inertial>
	</link>

	<link name="right_wheel">
		<visual>
			<geometry>
				<cylinder length="${wheel_h}" radius="${wheel_rad}"/> 
			</geometry>
			<origin rpy="1.57075 0 0" xyz="0 0 0"/>
			<material name="black"/>
		</visual>
		<collision>
			<geometry>
				<cylinder length="${wheel_h}" radius="${wheel_rad}"/>
			</geometry>
		</collision>
		<inertial>
			<mass value="${w_mass}"/>	
			<inertia ixx="0.0000787" ixy="0.0" ixz="0.0" iyy="0.0000787" iyz="0.0" izz="0.000144"/>
		</inertial>
	</link>

	<joint name="base_to_right_wheel" type="continuous">
		<parent link="base_link"/>
		<child link="right_wheel"/>
		<axis xyz="0 1 0"/>
		<origin xyz="0 0.155 -0.018"/>
	</joint>

	<link name="left_wheel">
		<visual>
			<geometry>
				<cylinder length="${wheel_h}" radius="${wheel_rad}"/> 
			</geometry>
			<origin rpy="1.57075 0 0" xyz="0 0 0"/>
			<material name="black"/>
		</visual>
		<collision>
			<geometry>
				<cylinder length="${wheel_h}" radius="${wheel_rad}"/>
			</geometry>
		</collision>
		<inertial>
			<mass value="${w_mass}"/>	
			<inertia ixx="0.0000787" ixy="0.0" ixz="0.0" iyy="0.0000787" iyz="0.0" izz="0.000144"/>
		</inertial>
	</link>

	<joint name="base_to_left_wheel" type="continuous">
		<parent link="base_link"/>
		<child link="left_wheel"/>
		<origin xyz="0 -0.155 -0.018"/>
	</joint>
	
</robot>
